# 一、检查异常的两种方法

## 1.1 使用`abort()`

1. 位于`cstdlib`库中
2. 调用`abort()`函数时，将向标准错误流发送信息`abnormal program termination`，并直接终止程序
3. 也可以使用`exit()`函数，区别是该函数刷新文件缓冲区但不显示消息
```c++
#include <iostream>
using namespace std;
int main()
{
	int a, b;
	cin >> a >> b;
	if (!b)
		abort();
	else
		cout << 1.0 * a / b;
	return 0;
}
```

## 1.2 返回错误码

可以使用函数的返回值来判断函数是否执行成功，如可令一函数为bool函数，当执行成功时返回true，否则返回false，检查返回值即可确定是否发生异常

# 二、异常机制

>*对异常的处理包括三部分：*
>*1. 引发异常*
>*2. 使用处理程序捕获异常*
>*3. 使用try块*

## 2.1 基础

1. 当程序出现错误时，使用关键字`throw`来表示引发异常，紧随其后的值（如字符串、对象）表示了异常的特征
```c++
double division(double x, double y)
{
	if (!y)
		throw "Error! y == 0 is not allowed";
	else
		return x / y;
}
```
2. 在try块中调用可能出现异常的语句，并且紧跟者一个或多个catch块（也被称为异常处理块）
```c++
try
{
	statement
}
catch (argument-list)
{

}
```

代码示例：
```c++
#include <iostream>
using namespace std;
double division(double x, double y)
{
	if (!y)
		throw "Error! The divisor can't be zero."
	else
		return x / y;
}

int main()
{
	double a, b;
	cin >> a >> b;
	
	try
	{
		cout << division(x, y);
	}
	catch (const char* s)
	{
		cout << s << endl;
	}
	
	return 0;
}
```
catch关键字后紧跟着用于标记异常特征的字符串（也可以是对象）

3. 使用`throw`返回对象
```c++
void function()
{
	if (statement1)
		throw int(-1); // 显式调用了int的构造函数
	else if (statement2)
		throw double(-1.0);
	else
		……
}

int main()
{
	try
	{
		function();
	}
	catch (const int& n)
	{
		……
	}
	catch (const double& d)
	{
		……
	}
	return 0;
};
```
这样，当throw返回了int类型的值时，将调用第一个catch块，忽视第二个catch块；反之，当throw返回了double类型的值时，将直接调用第二个catch块。
当然也可以将int，double类型替换为其他标准类型或者用户自定义的类（通常使用自定义的类，以方便设计相应的catch块）
当throw返回的类型可能是一个基类或者该基类的一个派生类时，应该把**捕获基类异常的catch块放在最后**，把派生链中的最低的派生类放在最前面

## 2.2 栈解退

>*当try块使用了调用了对**引发异常的函数1**进行调用的**函数2**时，程序流程将从引发异常的函数跳回到**try块和处理程序的函数**而不是函数2中*

C++通常通过将信息放在栈中来处理函数调用。具体地说，程序将调用函数的指令的地址（返回地址）放到栈中。当被调用的函数执行完毕后，程序将使用该地址来确定从哪里开始继续执行。另外，函数调用将函数参数放到栈中。在栈中，这些函数参数被视为自动变量。如果被调用的函数创建了新的自动变量，则这些变量也将被添加到栈中。如果被调用的函数调用了另一个函数，则后者的信息将被添加到栈中，依此类推。当函数结束时，程序流程将跳到该函数被调用时存储的地址处，同时栈顶的元素被释放。因此，函数通常都返回到调用它的函数，依此类推，同时每个函数都在结束时释放其自动变量。如果自动变量是类对象，则类的析构函数（如果有的话）将被调用。

现在假设函数由于出现异常（而不是由于返回）而终止，则程序也将释放栈中的内存，但不会在释放栈的第一个返回地址后停止，而是继续释放栈，直到找到一个位于try块（参见下图）中的返回地址。随后，控制权将转到块尾的异常处理程序，而不是函数调用后面的第一条语句。这个过程被称为栈解退。引发机制的一个非常重要的特性是，和函数返回一样，对于栈中的自动类对象，类的析构函数将被调用。然而，函数返回仅仅处理该函数放在栈中的对象，而throw语句则处理try块和throw之间整个函数调用序列放在栈中的对象。***如果没有栈解退这种特性，则引发异常后，对于中间函数调用放在栈中的自动类对象，其析构函数将不会被调用。***
![[栈解退.png]]

比如，在main函数中的try语句调用了函数`func1`，而`func1`又调用了`func2`并在`fun2`中发生了异常，如果`func1`中没有catch块，将跳回到main函数中检查是否有catch块，而当main中有catch块时，将调用相应的catch块，否则将调用abort()函数；如果`func1`中有catch块，将跳回到`func1`函数中的catch块中进行异常处理。

如果`func1`中的catch块中又写入了语句`throw;`则又将该异常返回到main函数中的catch块中。

## 2.3 其他异常特性

1. 引发异常时，编译器总是创建一个临时拷贝，即使catch语句中使用的参数类型是引用，但仍然建议使用引用类型，因为：
	1. 引用传递的效率更高
	2. 基类引用可以指向派生类对象
2. 可以在catch块中不申明捕获哪种异常，而是使用`...`来代替
```c++
try
{
	statement;
}
catch (...)
{
	statement;
}
```
这样无论哪种异常返回，都将进入这个catch块，可用于避免漏写了某个异常对应的catch块

# 三、异常类

## 3.1 exception类

1. 需要包含头文件`exception`
2. 可以将exception类作为异常类的基类，以创建异常派生类
```c++
class error: public std::exception
{
	……
}
```
3. 在exception()类中有一个虚方法`what()`，该方法返回一个字符串，可以在派生类中修改它的实现
```c++
class bad_number: public std::exception
{
public:
	const char* what() { return "Bad number input!"; }	
};
```

## 3.2 stdexcpt异常类

在头文件stdexcept中，定义了其他的几个异常类，如`logic_error`类，`runtime_error`类，均是以公有派生方式从`exception`类中派生过来的
```c++
class logic_error: public std::exception
{
public:
	explicit logic_error(const string& what_arg);
……
};

class runtime_error: public std::exception
{
public:
	explicit: runtime_error(const string& what_arg);
……
}
```
还有其他几个类，如`domain_error`, `invalid_argument`, `length_error`, `out_of_bounds`
这些类的构造函数都使用了string类型的参数，该参数用于提供what()方法返回的C风格字符串
`runtime_error`系列还有几个函数：`range_error`, `overflow_error`, `underflow_error`

| 异常类名         | 引发时机                                 |
| ---------------- | ---------------------------------------- |
| domain_error     | 当传入值不在定义域中时                   |
| invalid_argument | 当给函数传递了一个意料外的值             |
| length_error     | 当没有足够的空间时                       |
| out_of_bounds    | 当index不在范围内时                      |
| underflow_error  | 计算浮点数时小于了浮点数能表示的最低下限 |
| overflow_error   | 当计算数值时超出了该类型的最大值时       |
| range_error      | 计算结果不在函数的范围内，但又没有发生上溢或下溢                                         |

>*一般而言，logic_error系列的异常类表示可以通过编程修复的问题，而runtime_error系列表示无法避免的问题*

示例
```c++
try
{
	……
}
catch(out_of_bounds& ob)
{
	……
}
catch(logic_error& le)
{
	……
}
catch(exception& e)
{
	……
}
```

## 3.3 bad_alloc异常和new

>*对于使用new引发的内存分配问题，可让new引发bad_alloc异常*

1. 头文件`new`包含了`bad_alloc`类的声明，该类从exception类公有继承而来，示例：
```c++
#include <iostream>
using namespace std;
int main()
{
	try
	{
		double* a = new double[1000000000];
	}
	catch(bad_alloc& ba)
	{
		cout << "Caught the exception!" << endl;
		cout << ba.what() << endl;
		exit(EXIT_FAILURE);
	}
}
```

# 四、异常、类和继承

>*有三种方式使这三者相关联：
>1. 从一个异常类可以派生出另一个
>2. 可以在类声明中嵌套异常类声明来组合异常
>3. 这种嵌套声明本身就可以被继承还可用作基类*